Workbook

Sheet Welcome
B2: AI Readiness Discovery
B3: Based on the SPARK framework — for Small & Medium Businesses
B6: About this discovery
B7: A 15-minute guided check-in. Run it 1-on-1 with an advisor, or fill it in
B8: yourself before your advisor meeting.
B10: By the end you'll have:
B11: • An overall AI Readiness score (0–100%) with a band
B12: • A breakdown across the 5 SPARK steps
B13: • Your Top 3 Pain Points (Leaks) — where AI can help most
B14: • Detail on your top 2 pains, including grant-screening data
B15: • Your suggested next step
B18: How to use
... B30: Continue → the 'Questionnaire' tab

Sheet Questionnaire
B2: AI Readiness Discovery — Questionnaire
B3: Fill in Parts 1–5. Results auto-calculate in 'Your Results' tab.
K6: Customer communication | L6: =$C$42 -> 0 | M6: =IFERROR(L6-ROW()/1000,0) -> -0.006
B7: PART 1 OF 6 | K7: Sales & quotes | L7: =$C$44 -> 0 | M7: =IFERROR(L7-ROW()/1000,0) -> -0.007
B8: Business basics | K8: Admin & paperwork | L8: =$C$46 -> 0 | M8: =IFERROR(L8-ROW()/1000,0) -> -0.008
K9: Content & marketing | L9: =$C$48 -> 0 | M9: =IFERROR(L9-ROW()/1000,0) -> -0.009
B10: Business name | K10: Meetings & notes | L10: =$C$50 -> 0 | M10: =IFERROR(L10-ROW()/1000,0) -> -0.01
B11: UEN | K11: Data work | L11: =$C$52 -> 0 | M11: =IFERROR(L11-ROW()/1000,0) -> -0.011
B12: Contact number | K12: People & onboarding | L12: =$C$54 -> 0 | M12: =IFERROR(L12-ROW()/1000,0) -> -0.012
B13: Email address | K13: Knowledge & docs | L13: =$C$56 -> 0 | M13: =IFERROR(L13-ROW()/1000,0) -> -0.013
B14: Industry | D14: Dropdown — F&B, Retail, etc.
B15: Total employees | D15: Dropdown — band
B16: Local employees | D16: Number
B17: Foreign employees | D17: Number
B18: Advisor name
B21: PART 2 OF 6
B22: AI Readiness — rate 1 (Strongly disagree) to 5 (Strongly agree)
B24: Statement | C24: Rating (1–5) | D24: SPARK step
B25: We know which tasks in our business take up the most time. | D25: S
B26: When work feels slow or repetitive, we stop and ask if there's a better way. | D26: S
B27: We're willing to test a new tool on a small task first. | D27: P
B28: In the last 6 months, we tried something new and it worked. | D28: P
B29: When something works, we write it down so other staff can do it the same way. | D29: A
B30: Every new tool or process has one person in charge. | D30: A
B31: We have a rough idea of how much time each task takes. | D31: R
B32: We check if our tools are actually saving us time or money. | D32: R
B33: Someone in our team keeps up with what's new in technology. | D33: K
B34: We keep improving how we work — not just once and then stop. | D34: K
B38: PART 3 OF 6
B39: Problem Points (Leaks) — rate 1 (Not a problem) to 5 (Major drain)
B41: Pain area | C41: Pain rating (1–5)
B42: Customer communication
B43: Replying to emails and WhatsApp. Same questions again and again. Chasing for replies.
B44: Sales & quotes
B45: Writing quotes and proposals. Replying to enquiries. Putting contracts together.
B46: Admin & paperwork
B47: Invoices. Receipts. Monthly reports. Chasing paperwork.
B48: Content & marketing
B49: Facebook and Instagram posts. Newsletters. Website wording. Flyers.
B50: Meetings & notes
...

Sheet Your Results
B2: Your AI Readiness Discovery
B3: Auto-calculated from the Questionnaire tab
B6: Overall AI Readiness
B7: =ROUND(SUM(Questionnaire!C25:C34)/50*100,0)/100 -> 0 | C7: =IF(SUM(Questionnaire!C25:C34)=0,"—",IF(SUM(Questionnaire!C25:C34)/50<0.3,"Just starting",IF(SUM(Questionnaire!C25:C34)/50<0.55,"Getting going",IF(SUM(Questionnaire!C25:C34)/50<0.75,"Building momentum","Well underway")))) -> —
B9: SPARK breakdown
B10: Step | C10: Score | D10: of 10 | E10: What it asks
B11: S — Spot the leaks | C11: =SUM(Questionnaire!C25,Questionnaire!C26) -> 0 | D11: / 10 | E11: Are you systematically finding where time goes?
B12: P — Pilot small wins | C12: =SUM(Questionnaire!C27,Questionnaire!C28) -> 0 | D12: / 10 | E12: Are you willing to test before you commit?
B13: A — Apply what works | C13: =SUM(Questionnaire!C29,Questionnaire!C30) -> 0 | D13: / 10 | E13: Do good ideas turn into team habits?
B14: R — Review results | C14: =SUM(Questionnaire!C31,Questionnaire!C32) -> 0 | D14: / 10 | E14: Are you measuring impact honestly?
B15: K — Keep building | C15: =SUM(Questionnaire!C33,Questionnaire!C34) -> 0 | D15: / 10 | E15: Is improvement a habit, not a project?
B17: Top 3 Pain Points (Leaks)
B18: Rank | C18: Pain area | D18: Pain | E18: Action
B19: #1 | C19: =IFERROR(INDEX(Questionnaire!K6:K13,MATCH(LARGE(Questionnaire!M6:M13,1),Questionnaire!M6:M13,0)),"—") -> Customer communication | D19: =IFERROR(LARGE(Questionnaire!L6:L13,1)&"/5","—") -> 0/5 | E19: Start your pilot here.
B20: #2 | C20: =IFERROR(INDEX(Questionnaire!K6:K13,MATCH(LARGE(Questionnaire!M6:M13,2),Questionnaire!M6:M13,0)),"—") -> Sales & quotes | D20: =IFERROR(LARGE(Questionnaire!L6:L13,2)&"/5","—") -> 0/5 | E20: Save this for your second pilot.
B21: #3 | C21: =IFERROR(INDEX(Questionnaire!K6:K13,MATCH(LARGE(Questionnaire!M6:M13,3),Questionnaire!M6:M13,0)),"—") -> Admin & paperwork | D21: =IFERROR(LARGE(Questionnaire!L6:L13,3)&"/5","—") -> 0/5 | E21: Worth keeping on the list.
B23: Top 2 pain points — your detail
B24: #1 | C24: =Questionnaire!C65 -> Customer communication
B25: What it looks like: | C25: =Questionnaire!C66 -> 0
B26: Desired outcomes: | C26: =Questionnaire!C67 -> 0
B27: Grant-screening: | C27: =IF(Questionnaire!C68="","—",Questionnaire!C68&" affected · "&IF(Questionnaire!C69="","?",Questionnaire!C69)&" local · "&IF(Questionnaire!C70="","?",Questionnaire!C70)&" >12mo · ACRA: "&IF(Questionnaire!C71="","?",Questionnaire!C71)) -> —
B29: #2 | C29: =Questionnaire!C73 -> Sales & quotes
B30: What it looks like: | C30: =Questionnaire!C74 -> 0
B31: Desired outcomes: | C31: =Questionnaire!C75 -> 0
B32: Grant-screening: | C32: =IF(Questionnaire!C76="","—",Questionnaire!C76&" affected · "&IF(Questionnaire!C77="","?",Questionnaire!C77)&" local · "&IF(Questionnaire!C78="","?",Questionnaire!C78)&" >12mo · ACRA: "&IF(Questionnaire!C79="","?",Questionnaire!C79)) -> —
B35: Business & logistics summary
B36: Business name | C36: =IF(Questionnaire!C10="","—",Questionnaire!C10) -> —
B37: UEN | C37: =IF(Questionnaire!C11="","—",Questionnaire!C11) -> —
B38: Contact number | C38: =IF(Questionnaire!C12="","—",Questionnaire!C12) -> —
B39: Email | C39: =IF(Questionnaire!C13="","—",Questionnaire!C13) -> —
B40: Industry | C40: =IF(Questionnaire!C14="","—",Questionnaire!C14) -> —
B41: Total employees | C41: =IF(Questionnaire!C15="","—",Questionnaire!C15) -> —
B42: Local employees | C42: =IF(Questionnaire!C16="","—",Questionnaire!C16) -> —
B43: Foreign employees | C43: =IF(Questionnaire!C17="","—",Questionnaire!C17) -> —
B44: Advisor | C44: =IF(Questionnaire!C18="","—",Questionnaire!C18) -> —
B45: Budget | C45: =IF(Questionnaire!C85="","—",Questionnaire!C85) -> —
B46: Grant awareness — PSG | C46: =IF(Questionnaire!C87="","—",Questionnaire!C87) -> —
B47: Grant awareness — EDG | C47: =IF(Questionnaire!C88="","—",Questionnaire!C88) -> —
B48: Grant awareness — ECI | C48: =IF(Questionnaire!C89="","—",Questionnaire!C89) -> —
B49: Grant awareness — SFEC | C49: =IF(Questionnaire!C90="","—",Questionnaire!C90) -> —
...
